2025-08-22 23:53:37,515 DEBUG: DEBUG сообщение от django.security [test_logging_manual]
2025-08-22 23:53:37,515 INFO: INFO сообщение от django.security [test_logging_manual]
2025-08-22 23:53:37,515 WARNING: WARNING сообщение от django.security [test_logging_manual]
2025-08-22 23:53:37,515 ERROR: ERROR сообщение от django.security [test_logging_manual]
Traceback (most recent call last):
  File "C:\Users\Sergei\Desktop\Breaking_News_Portal\NewsPaper\NewsPortal\management\commands\test_logging_manual.py", line 30, in handle
    raise ValueError("Тестовая ошибка")
ValueError: Тестовая ошибка
2025-08-22 23:54:00,388 DEBUG: DEBUG сообщение от django.security [test_logging_manual]
2025-08-22 23:54:00,388 INFO: INFO сообщение от django.security [test_logging_manual]
2025-08-22 23:54:00,388 WARNING: WARNING сообщение от django.security [test_logging_manual]
2025-08-22 23:54:00,388 ERROR: ERROR сообщение от django.security [test_logging_manual]
Traceback (most recent call last):
  File "C:\Users\Sergei\Desktop\Breaking_News_Portal\NewsPaper\NewsPortal\management\commands\test_logging_manual.py", line 30, in handle
    raise ValueError("Тестовая ошибка")
ValueError: Тестовая ошибка
2025-08-22 23:57:16,137 DEBUG: DEBUG сообщение от django.security [test_logging_manual]
2025-08-22 23:57:16,137 INFO: INFO сообщение от django.security [test_logging_manual]
2025-08-22 23:57:16,138 WARNING: WARNING сообщение от django.security [test_logging_manual]
2025-08-22 23:57:16,138 ERROR: ERROR сообщение от django.security [test_logging_manual]
Traceback (most recent call last):
  File "C:\Users\Sergei\Desktop\Breaking_News_Portal\NewsPaper\NewsPortal\management\commands\test_logging_manual.py", line 30, in handle
    raise ValueError("Тестовая ошибка")
ValueError: Тестовая ошибка
2025-08-22 23:57:30,949 DEBUG: DEBUG сообщение от django.security [test_logging_manual]
2025-08-22 23:57:30,949 INFO: INFO сообщение от django.security [test_logging_manual]
2025-08-22 23:57:30,949 WARNING: WARNING сообщение от django.security [test_logging_manual]
2025-08-22 23:57:30,949 ERROR: ERROR сообщение от django.security [test_logging_manual]
Traceback (most recent call last):
  File "C:\Users\Sergei\Desktop\Breaking_News_Portal\NewsPaper\NewsPortal\management\commands\test_logging_manual.py", line 30, in handle
    raise ValueError("Тестовая ошибка")
ValueError: Тестовая ошибка
